<?xml version="1.0" ?>
<robot name="milling_robot">

  <link name="base_link">
    <inertial>
      <origin xyz="-1.7248355702659004e-13 0.0 0.014025773195876333" rpy="0 0 0"/>
      <mass value="0.044853107363923866"/>
      <inertia ixx="4e-06" iyy="4e-06" izz="1e-06" ixy="-0.0" iyz="0.0" ixz="-0.0"/>
    </inertial>
    <visual>
      <origin xyz="0 0 0" rpy="0 0 0"/>
      <geometry>
        <mesh filename="package://milling_robot_description/meshes/base_link.stl" scale="0.001 0.001 0.001"/>
      </geometry>
    </visual>
    <collision>
      <origin xyz="0 0 0" rpy="0 0 0"/>
      <geometry>
        <mesh filename="package://milling_robot_description/meshes/base_link.stl" scale="0.001 0.001 0.001"/>
      </geometry>
    </collision>
  </link>

  <link name="link1">
    <inertial>
      <origin xyz="8.657369613890436e-12 -0.017892760985166803 -0.0049999999999999975" rpy="0 0 0"/>
      <mass value="0.03512808228790527"/>
      <inertia ixx="8e-06" iyy="1e-06" izz="9e-06" ixy="0.0" iyz="-0.0" ixz="-0.0"/>
    </inertial>
    <visual>
      <origin xyz="-0.0 -0.0 -0.03" rpy="0 0 0"/>
      <geometry>
        <mesh filename="package://milling_robot_description/meshes/link1.stl" scale="0.001 0.001 0.001"/>
      </geometry>
    </visual>
    <collision>
      <origin xyz="-0.0 -0.0 -0.03" rpy="0 0 0"/>
      <geometry>
        <mesh filename="package://milling_robot_description/meshes/link1.stl" scale="0.001 0.001 0.001"/>
      </geometry>
    </collision>
  </link>

  <link name="link2">
    <inertial>
      <origin xyz="-0.003000007693934777 -0.016687618629062623 2.070121837838279e-09" rpy="0 0 0"/>
      <mass value="0.021696703597929294"/>
      <inertia ixx="3e-06" iyy="0.0" izz="3e-06" ixy="0.0" iyz="-0.0" ixz="0.0"/>
    </inertial>
    <visual>
      <origin xyz="-0.003 0.045 -0.025" rpy="0 0 0"/>
      <geometry>
        <mesh filename="package://milling_robot_description/meshes/link2.stl" scale="0.001 0.001 0.001"/>
      </geometry>
    </visual>
    <collision>
      <origin xyz="-0.003 0.045 -0.025" rpy="0 0 0"/>
      <geometry>
        <mesh filename="package://milling_robot_description/meshes/link2.stl" scale="0.001 0.001 0.001"/>
      </geometry>
    </collision>
  </link>

  <link name="link3">
    <inertial>
      <origin xyz="-4.487079278032369e-11 -0.0024999999999999745 -1.0408340855860843e-17" rpy="0 0 0"/>
      <mass value="0.0006165375582669755"/>
      <inertia ixx="0.0" iyy="0.0" izz="0.0" ixy="0.0" iyz="0.0" ixz="-0.0"/>
    </inertial>
    <visual>
      <origin xyz="0.0 0.082 -0.025" rpy="0 0 0"/>
      <geometry>
        <mesh filename="package://milling_robot_description/meshes/link3.stl" scale="0.001 0.001 0.001"/>
      </geometry>
    </visual>
    <collision>
      <origin xyz="0.0 0.082 -0.025" rpy="0 0 0"/>
      <geometry>
        <mesh filename="package://milling_robot_description/meshes/link3.stl" scale="0.001 0.001 0.001"/>
      </geometry>
    </collision>
  </link>

  <link name="link4">
    <inertial>
      <origin xyz="-3.2620662266947424e-11 -0.0030623001462547206 4.051913665703566e-11" rpy="0 0 0"/>
      <mass value="0.003623226210979948"/>
      <inertia ixx="0.0" iyy="0.0" izz="0.0" ixy="0.0" iyz="0.0" ixz="0.0"/>
    </inertial>
    <visual>
      <origin xyz="0.0 0.082 -0.025" rpy="0 0 0"/>
      <geometry>
        <mesh filename="package://milling_robot_description/meshes/link4.stl" scale="0.001 0.001 0.001"/>
      </geometry>
    </visual>
    <collision>
      <origin xyz="0.0 0.082 -0.025" rpy="0 0 0"/>
      <geometry>
        <mesh filename="package://milling_robot_description/meshes/link4.stl" scale="0.001 0.001 0.001"/>
      </geometry>
    </collision>
  </link>

  <joint name="Q1" type="revolute">
    <origin xyz="0.0 0.0 0.03" rpy="0 0 0"/>
    <limit effort="1000.0" lower="-1.57" upper="1.57" velocity="0.5"/>
    <parent link="base_link"/>
    <child link="link1"/>
    <axis xyz="0.0 0.0 1.0"/>
  </joint>

  <joint name="Q2" type="revolute">
    <origin xyz="0.003 -0.045 -0.005" rpy="0 0 0"/>
    <limit effort="1000.0" lower="-1.57" upper="1.57" velocity="0.5"/>
    <parent link="link1"/>
    <child link="link2"/>
    <axis xyz="-1.0 0.0 0.0"/>
  </joint>

  <joint name="Q3" type="revolute">
    <origin xyz="-0.003 -0.037 0.0" rpy="0 0 0"/>
    <limit effort="1000.0" lower="-1.57" upper="1.57" velocity="0.5"/>
    <parent link="link2"/>
    <child link="link3"/>
    <axis xyz="0.0 -1.0 0.0"/>
  </joint>

  <joint name="D4" type="prismatic">
    <origin xyz="0.0 0.0 0.0" rpy="0 0 0"/>
    <parent link="link3"/>
    <child link="link4"/>
    <axis xyz="0.0 -1.0 0.0"/>
    <limit effort="1000.0" lower="-0.008" upper="0.02" velocity="0.5"/>
  </joint>
</robot>
